The likely bug is that the function is incorrectly named `range`, which conflicts with the built-in Python function of the same name, leading to unexpected behavior.
